Workbook

Sheet Pivots
A1: GA 55 | F1: Last Update on this sheet | G1: 46110
A3: FY | B3: Pay | C3: DA | D3: HRA | E3: ROP | F3: Bonus | G3: PL Arrer | H3: Sum of CCA | I3: SI Loan | J3: Gross Amount | K3: SI | L3: NPS | M3: GIS | N3: GIS Tax | O3: H.F.R.F. | P3: C M FUND | Q3: GPF 2004 | R3: RGHS | S3: Itax | T3: SI Loan EMI | U3: Total Deduction | V3: Net. Payable Amount | AI3: SI SSO id (new) | AM3: negative value shows extra entries | AZ3: NPS SSOid
A4: 2013-2014 | B4: 46838 | J4: 46838 | U4: 0 | V4: 46838 | X4: SI SSO id (old)
A5: 2014-2015 | B5: 114560 | J5: 114560 | M5: 220 | N5: 27.19 | O5: 538 | U5: 785.19 | V5: 113774.81 | AI5: Sum of Total Premium | AZ5: FY | BA5: Employee Contribution | BB5: Employer Contribution | BC5: Sum of Total
A6: 2015-2016 | B6: 139150 | C6: 69561 | D6: 5846 | E6: -1452 | J6: 213105 | L6: 12801 | M6: 220 | N6: 27.19 | U6: 13048.19 | V6: 200056.81 | X6: Row Labels | Y6: Sum of Trans | Z6: Sum of Premium | AA6: Sum of Incremental Premium | AB6: Sum of Arrers | AC6: Sum of Loan Installment | AD6: Sum of Loan Interest | AE6: Sum of Misc Arrear | AF6: Sum of Service Tax | AG6: Sum of Total Premium | AI6: Row Labels | AJ6: Jan | AK6: Feb | AL6: Mar | AM6: Apr | AN6: May | AO6: Jun | AP6: Jul | AQ6: Aug | AR6: Sep | AS6: Oct | AT6: Nov | AU6: Dec | AW6: Grand Total | AZ6: 2015-2016 | BA6: 12801 | BB6: 12801 | BC6: 25602
A7: 2016-2017 | B7: 142515 | C7: 186335 | D7: 13676 | F7: 3387 | J7: 345913 | K7: 13200 | L7: 31550 | M7: 220 | N7: 31.9 | U7: 45001.9 | V7: 300911.1 | X7: 2016-2017 | Y7: 0 | Z7: 13200 | AA7: 0 | AB7: 0 | AC7: 0 | AD7: 0 | AE7: 0 | AF7: 0 | AG7: 13200 | AI7: 2016-2017 | AJ7: 1100 | AK7: 1100 | AL7: 1100 | AM7: 1100 | AN7: 1100 | AO7: 1100 | AP7: 1100 | AQ7: 1100 | AR7: 1100 | AS7: 2200 | AU7: 1100 | AV7: 0 | AW7: 13200 | AZ7: 2016-2017 | BA7: 31550 | BB7: 31550 | BC7: 63100
A8: 2017-2018 | B8: 238420 | C8: 119658 | D8: 19537 | F8: 6774 | J8: 384389 | K8: 31800 | L8: 34279 | M8: 220 | N8: 33 | U8: 66332 | V8: 318057 | X8: 2017-2018 | Y8: 0 | Z8: 31800 | AA8: 0 | AB8: 0 | AC8: 0 | AD8: 0 | AE8: 0 | AF8: 0 | AG8: 31800 | AI8: 2017-2018 | AJ8: 2650 | AK8: 2650 | AL8: 2650 | AM8: 2650 | AN8: 2650 | AO8: 2650 | AP8: 2650 | AQ8: 2650 | AR8: 2650 | AS8: 2650 | AT8: 2650 | AU8: 2650 | AW8: 31800 | AZ8: 2017-2018 | BA8: 34279 | BB8: 34279 | BC8: 68558
A9: 2018-2019 | B9: 524505 | C9: -106361 | D9: 28128 | F9: 6774 | G9: 287 | J9: 453333 | K9: 36000 | L9: 40111 | M9: 220 | U9: 76331 | V9: 377002 | X9: 2018-2019 | Y9: 0 | Z9: 36000 | AA9: 0 | AB9: 0 | AC9: 0 | AD9: 0 | AE9: 0 | AF9: 0 | AG9: 36000 | AI9: 2018-2019 | AJ9: 3000 | AK9: 6000 | AL9: 3000 | AM9: 3000 | AN9: 3000 | AO9: 3000 | AP9: 3000 | AQ9: 3000 | AR9: 3000 | AS9: 3000 | AT9: 3000 | AV9: 0 | AW9: 36000 | AZ9: 2018-2019 | BA9: 40111 | BB9: 40111 | BC9: 80222
A10: 2019-2020 | B10: 377650 | C10: 47094 | D10: 28992 | F10: 6774 | J10: 460510 | K10: 36000 | L10: 40766 | M10: 220 | U10: 76986 | V10: 383524 | X10: 2019-2020 | Y10: 0 | Z10: 36000 | AA10: 0 | AB10: 0 | AC10: 0 | AD10: 0 | AE10: 0 | AF10: 0 | AG10: 36000 | AI10: 2019-2020 | AJ10: 3000 | AK10: 3000 | AL10: 3000 | AM10: 3000 | AN10: 3000 | AO10: 3000 | AP10: 3000 | AQ10: 3000 | AR10: 3000 | AS10: 3000 | AT10: 3000 | AU10: 3000 | AW10: 36000 | AZ10: 2019-2020 | BA10: 40766 | BB10: 40766 | BC10: 81532
A11: 2020-2021 | B11: 388900 | C11: 78313 | D11: 29857 | F11: 6774 | J11: 503844 | K11: 60000 | L11: 44891 | M11: 220 | P11: 4542 | Q11: 5081 | U11: 114734 | V11: 389110 | X11: 2020-2021 | Y11: 0 | Z11: 55000 | AA11: 0 | AB11: 0 | AC11: 0 | AD11: 0 | AE11: 5000 | AF11: 0 | AG11: 55000 | AI11: 2020-2021 | AJ11: 5000 | AK11: 5000 | AL11: 5000 | AM11: 0 | AN11: 5000 | AO11: 10000 | AP11: 5000 | AQ11: 5000 | AR11: 5000 | AS11: 5000 | AT11: 5000 | AU11: 5000 | AW11: 60000 | AZ11: 2020-2021 | BA11: 44891 | BB11: 44891 | BC11: 89782
A12: 2021-2022 | B12: 399700 | C12: 104125 | D12: 33304 | F12: 6774 | J12: 543903 | K12: 60000 | L12: 48544 | M12: 2100 | Q12: 6003 | R12: 1760 | U12: 118407 | V12: 425496 | X12: 2021-2022 | Y12: 0 | Z12: 60000 | AA12: 0 | AB12: 0 | AC12: 0 | AD12: 0 | AE12: 0 | AF12: 0 | AG12: 60000 | AI12: 2021-2022 | AJ12: 5000 | AK12: 5000 | AL12: 5000 | AM12: 5000 | AN12: 5000 | AO12: 5000 | AP12: 5000 | AQ12: 5000 | AR12: 5000 | AS12: 5000 | AT12: 5000 | AU12: 5000 | AW12: 60000 | AZ12: 2021-2022 | BA12: 44313 | BB12: 44313 | BC12: 88626
A13: 2022-2023 | B13: 419600 | C13: 155572 | D13: 36311 | F13: 6774 | J13: 618257 | K13: 60000 | M13: 1750 | Q13: 31711 | R13: 5496 | U13: 98957 | V13: 519300 | X13: 2022-2023 | Z13: 60000 | AG13: 60000 | AI13: 2022-2023 | AJ13: 5000 | AK13: 5000 | AL13: 5000 | AM13: 5000 | AN13: 5000 | AO13: 5000 | AP13: 5000 | AQ13: 5000 | AR13: 5000 | AS13: 5000 | AT13: 5000 | AU13: 5000 | AW13: 60000 | AZ13: 2022-2023
A14: 2023-2024 | B14: 425600 | C14: 192992 | D14: 38304 | F14: 6774 | J14: 663670 | K14: 60000 | M14: 2100 | Q14: 36798 | R14: 7896 | S14: 10000 | U14: 116794 | V14: 546876 | X14: 2023-2024 | Z14: 60000 | AG14: 60000 | AI14: 2023-2024 | AJ14: 5000 | AK14: 5000 | AL14: 5000 | AM14: 5000 | AN14: 5000 | AO14: 5000 | AP14: 5000 | AQ14: 5000 | AR14: 5000 | AS14: 5000 | AT14: 5000 | AU14: 5000 | AW14: 60000 | AZ14: Grand Total | BA14: 248711 | BB14: 248711 | BC14: 497422
A15: 2024-2025 | B15: 438400 | C15: 230920 | D15: 40932 | F15: 6774 | J15: 717026 | K15: 60000 | M15: 2100 | Q15: 34186 | R15: 7896 | S15: 27500 | U15: 131682 | V15: 585344 | X15: 2024-2025 | Z15: 60000 | AG15: 60000 | AI15: 2024-2025 | AJ15: 5000 | AK15: 5000 | AL15: 5000 | AM15: 5000 | AN15: 5000 | AO15: 5000 | AP15: 5000 | AQ15: 5000 | AR15: 5000 | AS15: 10000 | AU15: 5000 | AV15: 0 | AW15: 60000
A16: 2025-2026 | B16: 470050 | C16: 269124 | D16: 71147 | F16: 6774 | H16: 6839 | I16: 434500 | J16: 1258434 | K16: 60000 | M16: 2100 | Q16: 32528 | R16: 7896 | T16: 65178 | U16: 167702 | V16: 1090732 | X16: 2026-2026 | Z16: 60000 | AC16: 65178 | AG16: 125178 | AI16: 2025-2026 | AJ16: 12242 | AK16: 12242 | AL16: 12242 | AM16: 5000 | AN16: 5000 | AO16: 5000 | AP16: 12242 | AQ16: 12242 | AR16: 12242 | AS16: 12242 | AT16: 12242 | AU16: 12242 | AW16: 125178
A17: Grand Total | B17: 4125888 | C17: 1347333 | D17: 346034 | E17: -1452 | F17: 64353 | G17: 287 | H17: 6839 | I17: 434500 | J17: 6323782 | K17: 477000 | L17: 252942 | M17: 11690 | N17: 119.28 | O17: 538 | P17: 4542 | Q17: 146307 | R17: 30944 | S17: 37500 | T17: 65178 | U17: 1026760.3 | V17: 5297021.7 | X17: Grand Total | Y17: 0 | Z17: 472000 | AA17: 0 | AB17: 0 | AC17: 65178 | AD17: 0 | AE17: 5000 | AF17: 0 | AG17: 537178 | AI17: Grand Total | AJ17: 46992 | AK17: 49992 | AL17: 46992 | AM17: 34750 | AN17: 39750 | AO17: 44750 | AP17: 46992 | AQ17: 46992 | AR17: 46992 | AS17: 53092 | AT17: 40892 | AU17: 43992 | AV17: 0 | AW17: 542178
A31: Pivot On GA-55 Sheet | E31: Pivot On SBBJ Sheet
A33: Row Labels | B33: Sum of Net. Payable Amount | E33: Row Labels | F33: Sum of Credit
A34: Diwali Bonus | B34: 49109 | E34: Diwali Bonus | F34: 49109
A35: 42668 | B35: 3387 | E35: 42668 | F35: 3387
A36: 43021 | B36: 6774 | E36: 43021 | F36: 6774
A37: 43407 | B37: 6774 | E37: 43407 | F37: 6774
A38: 43766 | B38: 6774 | E38: 43766 | F38: 6774
A39: 44153 | B39: 1693 | E39: 44153 | F39: 1693
A40: 44501 | B40: 3387 | E40: 44501 | F40: 3387
A41: 44854 | B41: 5080 | E41: 44854 | F41: 5080
A42: 45239 | B42: 5080 | E42: 45239 | F42: 5080
A43: 45589 | B43: 5080 | E43: 45589 | F43: 5080
A44: 45947 | B44: 5080 | E44: 45947 | F44: 5080
A45: Grand Total | B45: 49109 | E45: Grand Total | F45: 49109

Sheet SI Passbook
K1: Last Update on this sheet | L1: 46110 | N1: correction needed | O1: =IF(L5=0,0,1) -> 0
G3: automatic from GA 55 sheet
K4: sum of si of this sheet | L4: =SUM(H:H) -> 477000
K5: diff (SI of this sheet)-(pivot si) | L5: =L4-GETPIVOTDATA(" SI",Pivots!$A$3) -> 0
A6: S. No. | B6: Bill No | C6: Bill Date | D6: TV No | E6: TV Date | F6: FY | G6: Name of month | H6: SI
A7: ='GA55'!A3 -> 1 | B7: ='GA55'!B3 -> 91 | C7: ='GA55'!C3 -> 41711 | D7: ='GA55'!D3 -> 48188 | E7: ='GA55'!E3 -> 41713 | F7: ='GA55'!F3 -> 2013-2014 | G7: ='GA55'!G3 -> 41518 | H7: ='GA55'!Q3 -> 0
A8: ='GA55'!A4 -> 2 | B8: ='GA55'!B4 -> 92 | C8: ='GA55'!C4 -> 41711 | D8: ='GA55'!D4 -> 48189 | E8: ='GA55'!E4 -> 41713 | F8: ='GA55'!F4 -> 2013-2014 | G8: ='GA55'!G4 -> 41548 | H8: ='GA55'!Q4 -> 0
A9: ='GA55'!A5 -> 3 | B9: ='GA55'!B5 -> 93 | C9: ='GA55'!C5 -> 41711 | D9: ='GA55'!D5 -> 48190 | E9: ='GA55'!E5 -> 41713 | F9: ='GA55'!F5 -> 2013-2014 | G9: ='GA55'!G5 -> 41579 | H9: ='GA55'!Q5 -> 0
A10: ='GA55'!A6 -> 4 | B10: ='GA55'!B6 -> 94 | C10: ='GA55'!C6 -> 41711 | D10: ='GA55'!D6 -> 48191 | E10: ='GA55'!E6 -> 41713 | F10: ='GA55'!F6 -> 2013-2014 | G10: ='GA55'!G6 -> 41609 | H10: ='GA55'!Q6 -> 0
A11: ='GA55'!A7 -> 5 | B11: ='GA55'!B7 -> 95 | C11: ='GA55'!C7 -> 41711 | D11: ='GA55'!D7 -> 48174 | E11: ='GA55'!E7 -> 41713 | F11: ='GA55'!F7 -> 2013-2014 | G11: ='GA55'!G7 -> 41640 | H11: ='GA55'!Q7 -> 0
A12: ='GA55'!A8 -> 6 | B12: ='GA55'!B8 -> 96 | C12: ='GA55'!C8 -> 41711 | D12: ='GA55'!D8 -> 48175 | E12: ='GA55'!E8 -> 41713 | F12: ='GA55'!F8 -> 2013-2014 | G12: ='GA55'!G8 -> 41671 | H12: ='GA55'!Q8 -> 0
A13: ='GA55'!A9 -> 7 | B13: ='GA55'!B9 -> 2 | C13: ='GA55'!C9 -> 41732 | D13: ='GA55'!D9 -> 268 | E13: ='GA55'!E9 -> 41736 | F13: ='GA55'!F9 -> 2014-2015 | G13: ='GA55'!G9 -> 41699 | H13: ='GA55'!Q9 -> 0
A14: ='GA55'!A10 -> 8 | B14: ='GA55'!B10 -> 5 | C14: ='GA55'!C10 -> 41757 | D14: ='GA55'!D10 -> 3591 | E14: ='GA55'!E10 -> 41761 | F14: ='GA55'!F10 -> 2014-2015 | G14: ='GA55'!G10 -> 41730 | H14: ='GA55'!Q10 -> 0
A15: ='GA55'!A11 -> 9 | B15: ='GA55'!B11 -> 11 | C15: ='GA55'!C11 -> 41767 | D15: ='GA55'!D11 -> 11212 | E15: ='GA55'!E11 -> 41822 | F15: ='GA55'!F11 -> 2014-2015 | G15: ='GA55'!G11 -> 41760 | H15: ='GA55'!Q11 -> 0
A16: ='GA55'!A12 -> 10 | B16: ='GA55'!B12 -> 13 | C16: ='GA55'!C12 -> 41820 | D16: ='GA55'!D12 -> 17812 | E16: ='GA55'!E12 -> 41872 | F16: ='GA55'!F12 -> 2014-2015 | G16: ='GA55'!G12 -> 41791 | H16: ='GA55'!Q12 -> 0
A17: ='GA55'!A13 -> 11 | B17: ='GA55'!B13 -> 16 | C17: ='GA55'!C13 -> 41848 | D17: ='GA55'!D13 -> 14902 | E17: ='GA55'!E13 -> 41852 | F17: ='GA55'!F13 -> 2014-2015 | G17: ='GA55'!G13 -> 41821 | H17: ='GA55'!Q13 -> 0
A18: ='GA55'!A14 -> 12 | B18: ='GA55'!B14 -> 19 | C18: ='GA55'!C14 -> 41877 | D18: ='GA55'!D14 -> 19307 | E18: ='GA55'!E14 -> 41883 | F18: ='GA55'!F14 -> 2014-2015 | G18: ='GA55'!G14 -> 41852 | H18: ='GA55'!Q14 -> 0
... A729: ='GA55'!A725 -> 0 | B729: ='GA55'!B725 -> 0 | C729: ='GA55'!C725 -> 0 | D729: ='GA55'!D725 -> 0 | E729: ='GA55'!E725 -> 0 | F729: ='GA55'!F725 -> 0 | G729: ='GA55'!G725 -> 0 | H729: ='GA55'!Q725 -> 0

Sheet GA55
G1: Last Update on this sheet | H1: 46110 | X1: =COUNTA(Table1[GPF 2004]) -> 62 | AC1: =COUNTA(Table1[remark]) -> 8
A2: S. No. | B2: Bill No | C2: Bill Date | D2: TV No | E2: TV Date | F2: FY | G2: Name of month | H2: Pay | I2: DA | J2: HRA | K2: ROP | L2: Bonus | M2: PL Arrer | N2: SI Loan | O2: CCA | P2: Gross Amount | Q2: SI | R2: SI Loan EMI | S2: NPS | T2: GIS | U2: GIS Tax | V2: H.F.R.F. | W2: C M FUND | X2: GPF 2004 | Y2: RGHS | Z2: Itax | AA2: Total Deduction | AB2: Net. Payable Amount | AC2: remark
A3: =IFERROR(VALUE(A2),0)+1 -> 1 | B3: 91 | C3: 41711 | D3: 48188 | E3: 41713 | F3: 2013-2014 | G3: 41518 | H3: 2088 | P3: =SUM(H3:O3) -> 2088 | AA3: =SUM(Q3:Z3) -> 0 | AB3: =P3-AA3 -> 2088
A4: =IFERROR(VALUE(A3),0)+1 -> 2 | B4: 92 | C4: 41711 | D4: 48189 | E4: 41713 | F4: 2013-2014 | G4: 41548 | H4: 8950 | P4: =SUM(H4:O4) -> 8950 | AA4: =SUM(Q4:Z4) -> 0 | AB4: =P4-AA4 -> 8950
A5: =IFERROR(VALUE(A4),0)+1 -> 3 | B5: 93 | C5: 41711 | D5: 48190 | E5: 41713 | F5: 2013-2014 | G5: 41579 | H5: 8950 | P5: =SUM(H5:O5) -> 8950 | AA5: =SUM(Q5:Z5) -> 0 | AB5: =P5-AA5 -> 8950
A6: =IFERROR(VALUE(A5),0)+1 -> 4 | B6: 94 | C6: 41711 | D6: 48191 | E6: 41713 | F6: 2013-2014 | G6: 41609 | H6: 8950 | P6: =SUM(H6:O6) -> 8950 | AA6: =SUM(Q6:Z6) -> 0 | AB6: =P6-AA6 -> 8950
A7: =IFERROR(VALUE(A6),0)+1 -> 5 | B7: 95 | C7: 41711 | D7: 48174 | E7: 41713 | F7: 2013-2014 | G7: 41640 | H7: 8950 | P7: =SUM(H7:O7) -> 8950 | AA7: =SUM(Q7:Z7) -> 0 | AB7: =P7-AA7 -> 8950
A8: =IFERROR(VALUE(A7),0)+1 -> 6 | B8: 96 | C8: 41711 | D8: 48175 | E8: 41713 | F8: 2013-2014 | G8: 41671 | H8: 8950 | P8: =SUM(H8:O8) -> 8950 | AA8: =SUM(Q8:Z8) -> 0 | AB8: =P8-AA8 -> 8950
A9: =IFERROR(VALUE(A8),0)+1 -> 7 | B9: 2 | C9: 41732 | D9: 268 | E9: 41736 | F9: 2014-2015 | G9: 41699 | H9: 8950 | P9: =SUM(H9:O9) -> 8950 | AA9: =SUM(Q9:Z9) -> 0 | AB9: =P9-AA9 -> 8950
A10: =IFERROR(VALUE(A9),0)+1 -> 8 | B10: 5 | C10: 41757 | D10: 3591 | E10: 41761 | F10: 2014-2015 | G10: 41730 | H10: 8950 | P10: =SUM(H10:O10) -> 8950 | T10: 220 | U10: 27.19 | AA10: =SUM(Q10:Z10) -> 247.19 | AB10: =P10-AA10 -> 8702.81
A11: =IFERROR(VALUE(A10),0)+1 -> 9 | B11: 11 | C11: 41767 | D11: 11212 | E11: 41822 | F11: 2014-2015 | G11: 41760 | H11: 8950 | P11: =SUM(H11:O11) -> 8950 | AA11: =SUM(Q11:Z11) -> 0 | AB11: =P11-AA11 -> 8950
A12: =IFERROR(VALUE(A11),0)+1 -> 10 | B12: 13 | C12: 41820 | D12: 17812 | E12: 41872 | F12: 2014-2015 | G12: 41791 | H12: 8950 | P12: =SUM(H12:O12) -> 8950 | AA12: =SUM(Q12:Z12) -> 0 | AB12: =P12-AA12 -> 8950
A13: =IFERROR(VALUE(A12),0)+1 -> 11 | B13: 16 | C13: 41848 | D13: 14902 | E13: 41852 | F13: 2014-2015 | G13: 41821 | H13: 8950 | P13: =SUM(H13:O13) -> 8950 | AA13: =SUM(Q13:Z13) -> 0 | AB13: =P13-AA13 -> 8950
A14: =IFERROR(VALUE(A13),0)+1 -> 12 | B14: 19 | C14: 41877 | D14: 19307 | E14: 41883 | F14: 2014-2015 | G14: 41852 | H14: 8950 | P14: =SUM(H14:O14) -> 8950 | AA14: =SUM(Q14:Z14) -> 0 | AB14: =P14-AA14 -> 8950
A15: =IFERROR(VALUE(A14),0)+1 -> 13 | B15: 25 | C15: 41912 | D15: 25673 | E15: 41920 | F15: 2014-2015 | G15: 41883 | H15: 8950 | P15: =SUM(H15:O15) -> 8950 | V15: 269 | AA15: =SUM(Q15:Z15) -> 269 | AB15: =P15-AA15 -> 8681
A16: =IFERROR(VALUE(A15),0)+1 -> 14 | B16: 34 | C16: 41941 | D16: 30648 | E16: 41944 | F16: 2014-2015 | G16: 41913 | H16: 8950 | P16: =SUM(H16:O16) -> 8950 | V16: 269 | AA16: =SUM(Q16:Z16) -> 269 | AB16: =P16-AA16 -> 8681
A17: =IFERROR(VALUE(A16),0)+1 -> 15 | B17: 71 | C17: 42062 | D17: 43520 | E17: 42073 | F17: 2014-2015 | G17: 41944 | H17: 10740 | P17: =SUM(H17:O17) -> 10740 | AA17: =SUM(Q17:Z17) -> 0 | AB17: =P17-AA17 -> 10740
A18: =IFERROR(VALUE(A17),0)+1 -> 16 | B18: 59 | C18: 41999 | D18: 36092 | E18: 42005 | F18: 2014-2015 | G18: 41974 | H18: 10740 | P18: =SUM(H18:O18) -> 10740 | AA18: =SUM(Q18:Z18) -> 0 | AB18: =P18-AA18 -> 10740
A19: =IFERROR(VALUE(A18),0)+1 -> 17 | B19: 60 | C19: 42032 | D19: 38855 | E19: 42037 | F19: 2014-2015 | G19: 42005 | H19: 10740 | P19: =SUM(H19:O19) -> 10740 | AA19: =SUM(Q19:Z19) -> 0 | AB19: =P19-AA19 -> 10740
A20: =IFERROR(VALUE(A19),0)+1 -> 18 | B20: 70 | C20: 42061 | D20: 42763 | E20: 42066 | F20: 2014-2015 | G20: 42036 | H20: 10740 | P20: =SUM(H20:O20) -> 10740 | AA20: =SUM(Q20:Z20) -> 0 | AB20: =P20-AA20 -> 10740
A21: =IFERROR(VALUE(A20),0)+1 -> 19 | B21: 2 | C21: 42107 | D21: 2031 | E21: 42115 | F21: 2015-2016 | G21: 42064 | H21: 10740 | P21: =SUM(H21:O21) -> 10740 | AA21: =SUM(Q21:Z21) -> 0 | AB21: =P21-AA21 -> 10740
A22: =IFERROR(VALUE(A21),0)+1 -> 20 | B22: 16 | C22: 42123 | D22: 4188 | E22: 42128 | F22: 2015-2016 | G22: 42095 | H22: 10740 | P22: =SUM(H22:O22) -> 10740 | T22: 220 | U22: 27.19 | AA22: =SUM(Q22:Z22) -> 247.19 | AB22: =P22-AA22 -> 10492.81
A23: =IFERROR(VALUE(A22),0)+1 -> 21 | B23: 57 | C23: 42276 | D23: 23777 | E23: 42278 | F23: 2015-2016 | G23: 42125 | H23: 10740 | P23: =SUM(H23:O23) -> 10740 | AA23: =SUM(Q23:Z23) -> 0 | AB23: =P23-AA23 -> 10740
A24: =IFERROR(VALUE(A23),0)+1 -> 22 | B24: 58 | C24: 42276 | D24: 23776 | E24: 42278 | F24: 2015-2016 | G24: 42156 | H24: 10740 | P24: =SUM(H24:O24) -> 10740 | AA24: =SUM(Q24:Z24) -> 0 | AB24: =P24-AA24 -> 10740
A25: =IFERROR(VALUE(A24),0)+1 -> 23 | B25: 38 | C25: 42215 | D25: 15532 | E25: 42217 | F25: 2015-2016 | G25: 42186 | H25: 11820 | P25: =SUM(H25:O25) -> 11820 | AA25: =SUM(Q25:Z25) -> 0 | AB25: =P25-AA25 -> 11820
A26: =IFERROR(VALUE(A25),0)+1 -> 24 | B26: 46 | C26: 42242 | D26: 21641 | E26: 43360 | F26: 2015-2016 | G26: 42217 | H26: 11820 | P26: =SUM(H26:O26) -> 11820 | AA26: =SUM(Q26:Z26) -> 0 | AB26: =P26-AA26 -> 11820
A27: =IFERROR(VALUE(A26),0)+1 -> 25 | B27: 56 | C27: 42276 | D27: 23778 | E27: 42278 | F27: 2015-2016 | G27: 42248 | H27: 11820 | P27: =SUM(H27:O27) -> 11820 | AA27: =SUM(Q27:Z27) -> 0 | AB27: =P27-AA27 -> 11820
A28: =IFERROR(VALUE(A27),0)+1 -> 26 | B28: 64 | C28: 42305 | D28: 42265 | E28: 42390 | F28: 2015-2016 | G28: 42278 | H28: 11820 | P28: =SUM(H28:O28) -> 11820 | AA28: =SUM(Q28:Z28) -> 0 | AB28: =P28-AA28 -> 11820 | AC28: SI, gpf etc sheet me entry check kren
A29: =IFERROR(VALUE(A28),0)+1 -> 27 | B29: 76 | C29: 42336 | D29: 36395 | E29: 42349 | F29: 2015-2016 | G29: 42309 | H29: 11820 | P29: =SUM(H29:O29) -> 11820 | AA29: =SUM(Q29:Z29) -> 0 | AB29: =P29-AA29 -> 11820
A30: =IFERROR(VALUE(A29),0)+1 -> 28 | B30: 96 | C30: 42009 | D30: 49219 | E30: 42432 | F30: 2015-2016 | G30: 42339 | H30: 11170 | I30: 13292 | J30: 1117 | P30: =SUM(H30:O30) -> 25579 | S30: 2446 | AA30: =SUM(Q30:Z30) -> 2446 | AB30: =P30-AA30 -> 23133
A31: =IFERROR(VALUE(A30),0)+1 -> 29 | B31: 115 | C31: 42394 | D31: 43674 | E31: 42401 | F31: 2015-2016 | G31: 42370 | H31: 11170 | I31: 13292 | J31: 1117 | P31: =SUM(H31:O31) -> 25579 | S31: 2446 | AA31: =SUM(Q31:Z31) -> 2446 | AB31: =P31-AA31 -> 23133
A32: =IFERROR(VALUE(A31),0)+1 -> 30 | B32: 131 | C32: 42401 | D32: 48941 | E32: 42431 | F32: 2015-2016 | G32: 42401 | H32: 11170 | I32: 13292 | J32: 1117 | P32: =SUM(H32:O32) -> 25579 | S32: 2446 | AA32: =SUM(Q32:Z32) -> 2446 | AB32: =P32-AA32 -> 23133
A33: =IFERROR(VALUE(A32),0)+1 -> 31 | B33: 61 | C33: 42291 | D33: 26313 | E33: 42294 | F33: 2015-2016 | G33: Oct-15 Salary Arrer | H33: 3580 | P33: =SUM(H33:O33) -> 3580 | AA33: =SUM(Q33:Z33) -> 0 | AB33: =P33-AA33 -> 3580
A34: =IFERROR(VALUE(A33),0)+1 -> 32 | B34: 137 | C34: 44270 | D34: 55291 | E34: 42460 | F34: 2015-2016 | G34: Mar-16 Salary Arrer | I34: 29685 | J34: 2495 | K34: -1452 | P34: =SUM(H34:O34) -> 30728 | S34: 5463 | AA34: =SUM(Q34:Z34) -> 5463 | AB34: =P34-AA34 -> 25265
A35: =IFERROR(VALUE(A34),0)+1 -> 33 | B35: 2 | C35: 42472 | D35: 2179 | E35: 42485 | F35: 2016-2017 | G35: 42430 | H35: 11170 | I35: 13292 | J35: 1117 | P35: =SUM(H35:O35) -> 25579 | Q35: 1100 | S35: 2446 | AA35: =SUM(Q35:Z35) -> 3546 | AB35: =P35-AA35 -> 22033
A36: =IFERROR(VALUE(A35),0)+1 -> 34 | B36: 12 | C36: 42487 | D36: 3158 | E36: 42492 | F36: 2016-2017 | G36: 42461 | H36: 11170 | I36: 13963 | J36: 1117 | P36: =SUM(H36:O36) -> 26250 | Q36: 1100 | S36: 2513 | T36: 220 | U36: 31.9 | AA36: =SUM(Q36:Z36) -> 3864.9 | AB36: =P36-AA36 -> 22385.1
A37: =IFERROR(VALUE(A36),0)+1 -> 35 | B37: 13 | C37: 42544 | D37: 13185 | E37: 42549 | F37: 2016-2017 | G37: 42491 | H37: 11170 | I37: 13963 | J37: 1117 | P37: =SUM(H37:O37) -> 26250 | Q37: 1100 | S37: 2513 | AA37: =SUM(Q37:Z37) -> 3613 | AB37: =P37-AA37 -> 22637
A38: =IFERROR(VALUE(A37),0)+1 -> 36 | B38: 14 | C38: 42548 | D38: 14705 | E38: 42553 | F38: 2016-2017 | G38: 42522 | H38: 11170 | I38: 13963 | J38: 1117 | P38: =SUM(H38:O38) -> 26250 | Q38: 1100 | S38: 2513 | AA38: =SUM(Q38:Z38) -> 3613 | AB38: =P38-AA38 -> 22637
A39: =IFERROR(VALUE(A38),0)+1 -> 37 | B39: 17 | C39: 42583 | D39: 19959 | E39: 42586 | F39: 2016-2017 | G39: 42552 | H39: 11170 | I39: 13963 | J39: 1117 | P39: =SUM(H39:O39) -> 26250 | Q39: 1100 | S39: 2513 | AA39: =SUM(Q39:Z39) -> 3613 | AB39: =P39-AA39 -> 22637
A40: =IFERROR(VALUE(A39),0)+1 -> 38 | B40: 28 | C40: 42605 | D40: 23893 | E40: 42614 | F40: 2016-2017 | G40: 42583 | H40: 11510 | I40: 14388 | J40: 1151 | P40: =SUM(H40:O40) -> 27049 | Q40: 1100 | S40: 2590 | AA40: =SUM(Q40:Z40) -> 3690 | AB40: =P40-AA40 -> 23359
...

Sheet Leave Balance
B1: Last Update on this sheet | C1: 46110 | G1: difference | H1: =SUM(Z5:Z16) -> 2
L3: Pivot on GA55 | O3: Pivot on Left Table | V3: Manual Entry from Raj Kaj
A4: Leave Type | B4: Leave Earned / Cash Payment or Deductable PL | C4: Year | D4: From | E4: To | F4: No of Days/ Months | G4: Leave Earned / Cash Payment or Deductable PL2 | H4: Balance on retrun from leave column | I4: Remark | J4: matched with service book | L4: Row Labels | M4: Total Times PL Cash | O4: Row Labels | P4: Count | Q4: Sum of Leave | V4: Leave Balance | X4: Difference | Z4: count
A5: PL | B5: Leave Earned | C5: 2015 | D5: 42271 | E5: 42369 | F5: 3 Months and 7 Days | G5: 8 | H5: 8 | J5: Yes | L5: Surrender Leave | M5: 8 | O5: PL | P5: 35 | Q5: 174 | V5: PL | W5: 233 | X5: =GETPIVOTDATA("Sum of Leave",$O$4)-W5 -> -59 | Z5: =IF(X5<>0,1,0) -> 1
A6: PL | B6: Leave Earned | C6: 2016 | D6: 42370 | E6: 42551 | F6: 6 Months | G6: 15 | H6: =Table11[[#This Row],[Leave Earned / Cash Payment or Deductable PL2]]+H5 -> 23 | J6: Yes | L6: Grand Total | M6: 8 | O6: Payment | P6: 8 | Q6: -120 | V6: Medical | W6: 120 | X6: =GETPIVOTDATA("Sum of Leave",$O$15)-W6 -> 20 | Z6: =IF(X6<>0,1,0) -> 1
A7: PL | B7: Leave Earned | C7: 2016 | D7: 42552 | E7: 42735 | F7: 6 Months | G7: 15 | H7: =Table11[[#This Row],[Leave Earned / Cash Payment or Deductable PL2]]+H6 -> 38 | J7: Yes | O7: Leave Earned | P7: 23 | Q7: 328
A8: PL | B8: Leave Earned | C8: 2016 | G8: 10 | H8: =Table11[[#This Row],[Leave Earned / Cash Payment or Deductable PL2]]+H7 -> 48 | I8: Transfer From sangriya to Tibbi | J8: Yes | O8: Deductable | P8: 4 | Q8: -34
A9: PL | B9: Leave Earned | C9: 2017 | D9: 42736 | E9: 42916 | F9: 6 Months | G9: 15 | H9: =Table11[[#This Row],[Leave Earned / Cash Payment or Deductable PL2]]+H8 -> 63 | J9: Yes | O9: Grand Total | P9: 35 | Q9: 174
A10: PL | B10: Payment | C10: 2017 | D10: 42795 | G10: -15 | H10: =Table11[[#This Row],[Leave Earned / Cash Payment or Deductable PL2]]+H9 -> 48 | J10: Yes | V10: Payment of PL In GA 55 and Left most table | X10: =GETPIVOTDATA("Name of month",$L$4,"Name of month","Surrender Leave")-GETPIVOTDATA("Leave Earned / Cash Payment or Deductable PL",$O$4,"Leave Type","PL","Leave Earned / Cash Payment or Deductable PL","Payment") -> 0 | Z10: =IF(X10<>0,1,0) -> 0
A11: PL | B11: Leave Earned | C11: 2017 | D11: 42917 | E11: 43100 | F11: 6 Months | G11: 15 | H11: =Table11[[#This Row],[Leave Earned / Cash Payment or Deductable PL2]]+H10 -> 63 | J11: Yes | V11: (Mohit Attendance Sheet PL)-(This sheet PL) | X11: =IFERROR(GETPIVOTDATA("Present Status",'[1]Summary (New)'!$O$3,"Present Status","PL")+GETPIVOTDATA("Leave Earned / Cash Payment or Deductable PL2",$R$4,"Leave Type","PL","Leave Earned / Cash Payment or Deductable PL","Dedutable"),0) -> 0 | Z11: =IF(X11<>0,1,0) -> 0
A12: PL | B12: Deductable | C12: 2017 | D12: 42955 | E12: 42956 | F12: 2 Days | G12: -2 | H12: =Table11[[#This Row],[Leave Earned / Cash Payment or Deductable PL2]]+H11 -> 61 | I12: 2 Days Strike | J12: Yes
A13: PL | B13: Leave Earned | C13: 2018 | D13: 43101 | E13: 43281 | F13: 6 Months | G13: 15 | H13: =Table11[[#This Row],[Leave Earned / Cash Payment or Deductable PL2]]+H12 -> 76 | J13: Yes
A14: PL | B14: Payment | C14: 2018 | D14: 43132 | G14: -15 | H14: =Table11[[#This Row],[Leave Earned / Cash Payment or Deductable PL2]]+H13 -> 61 | J14: Yes
A15: PL | B15: Leave Earned | C15: 2018 | D15: 43282 | E15: 43465 | F15: 6 Months | G15: 15 | H15: =Table11[[#This Row],[Leave Earned / Cash Payment or Deductable PL2]]+H14 -> 76 | J15: Yes | O15: Row Labels | P15: Count | Q15: Sum of Leave
A16: PL | B16: Deductable | C16: 2018 | D16: 43368 | E16: 43378 | F16: 11 Days | G16: -11 | H16: =Table11[[#This Row],[Leave Earned / Cash Payment or Deductable PL2]]+H15 -> 65 | I16: 11 Days Strike | J16: Yes | O16: Medical | P16: 7 | Q16: 140
A17: PL | B17: Leave Earned | C17: 2019 | D17: 43466 | E17: 43646 | F17: 6 Months | G17: 15 | H17: =Table11[[#This Row],[Leave Earned / Cash Payment or Deductable PL2]]+H16 -> 80 | J17: Yes | O17: Leave Earned | P17: 7 | Q17: 140
A18: PL | B18: Payment | C18: 2019 | D18: 43466 | G18: -15 | H18: =Table11[[#This Row],[Leave Earned / Cash Payment or Deductable PL2]]+H17 -> 65 | J18: Yes | O18: Grand Total | P18: 7 | Q18: 140
A19: PL | B19: Leave Earned | C19: 2019 | D19: 43647 | E19: 43830 | F19: 6 Months | G19: 15 | H19: =Table11[[#This Row],[Leave Earned / Cash Payment or Deductable PL2]]+H18 -> 80 | J19: Yes
A20: PL | B20: Leave Earned | C20: 2020 | D20: 43831 | E20: 44012 | F20: 6 Months | G20: 15 | H20: =Table11[[#This Row],[Leave Earned / Cash Payment or Deductable PL2]]+H19 -> 95 | J20: Yes
A21: PL | B21: Payment | C21: 2020 | D21: 43862 | G21: -15 | H21: =Table11[[#This Row],[Leave Earned / Cash Payment or Deductable PL2]]+H20 -> 80 | J21: Yes
A22: PL | B22: Leave Earned | C22: 2020 | D22: 44013 | E22: 44196 | F22: 6 Months | G22: 15 | H22: =Table11[[#This Row],[Leave Earned / Cash Payment or Deductable PL2]]+H21 -> 95 | J22: Yes
A23: PL | B23: Payment | C23: 2020 | D23: 44044 | G23: -15 | H23: =Table11[[#This Row],[Leave Earned / Cash Payment or Deductable PL2]]+H22 -> 80 | J23: Yes
A24: PL | B24: Leave Earned | C24: 2021 | D24: 44197 | E24: 44377 | F24: 6 Months | G24: 15 | H24: =Table11[[#This Row],[Leave Earned / Cash Payment or Deductable PL2]]+H23 -> 95 | J24: Yes
A25: PL | B25: Payment | C25: 2021 | D25: 44348 | G25: -15 | H25: =Table11[[#This Row],[Leave Earned / Cash Payment or Deductable PL2]]+H24 -> 80 | J25: Yes
A26: PL | B26: Leave Earned | C26: 2021 | D26: 44378 | E26: 44561 | F26: 6 Months | G26: 15 | H26: =Table11[[#This Row],[Leave Earned / Cash Payment or Deductable PL2]]+H25 -> 95 | J26: Yes
A27: PL | B27: Leave Earned | C27: 2022 | D27: 44562 | E27: 44742 | F27: 6 Months | G27: 15 | H27: =Table11[[#This Row],[Leave Earned / Cash Payment or Deductable PL2]]+H26 -> 110 | J27: Yes
A28: PL | B28: Payment | C28: 2022 | D28: 44682 | G28: -15 | H28: =Table11[[#This Row],[Leave Earned / Cash Payment or Deductable PL2]]+H27 -> 95 | J28: Yes
A29: PL | B29: Leave Earned | C29: 2022 | D29: 44743 | E29: 44926 | F29: 6 Months | G29: 15 | H29: =Table11[[#This Row],[Leave Earned / Cash Payment or Deductable PL2]]+H28 -> 110 | J29: Yes
A30: PL | B30: Leave Earned | C30: 2023 | D30: 44927 | E30: 45107 | F30: 6 Months | G30: 15 | H30: =Table11[[#This Row],[Leave Earned / Cash Payment or Deductable PL2]]+H29 -> 125 | J30: Yes
A31: PL | B31: Deductable | C31: 2023 | D31: 45040 | E31: 45048 | F31: 9 Days | G31: -9 | H31: =Table11[[#This Row],[Leave Earned / Cash Payment or Deductable PL2]]+H30 -> 116 | I31: 9 Days Strike | J31: Yes
A32: PL | B32: Leave Earned | C32: 2023 | D32: 45108 | E32: 45291 | F32: 6 Months | G32: 15 | H32: =Table11[[#This Row],[Leave Earned / Cash Payment or Deductable PL2]]+H31 -> 131 | J32: Yes
A33: PL | B33: Leave Earned | C33: 2024 | D33: 45292 | E33: 45473 | F33: 6 Months | G33: 15 | H33: =Table11[[#This Row],[Leave Earned / Cash Payment or Deductable PL2]]+H32 -> 146 | J33: Yes
A34: PL | B34: Leave Earned | C34: 2024 | D34: 45474 | E34: 45657 | F34: 6 Months | G34: 15 | H34: =Table11[[#This Row],[Leave Earned / Cash Payment or Deductable PL2]]+H33 -> 161 | J34: Yes
A35: PL | B35: Leave Earned | C35: 2025 | D35: 45658 | E35: 45838 | F35: 6 Months | G35: 15 | H35: =Table11[[#This Row],[Leave Earned / Cash Payment or Deductable PL2]]+H34 -> 176 | J35: Yes
A36: PL | B36: Payment | C36: 2025 | D36: 45778 | G36: -15 | H36: =Table11[[#This Row],[Leave Earned / Cash Payment or Deductable PL2]]+H35 -> 161 | J36: Yes
A37: PL | B37: Leave Earned | C37: 2025 | D37: 45839 | E37: 46022 | F37: 6 Months | G37: 15 | H37: =Table11[[#This Row],[Leave Earned / Cash Payment or Deductable PL2]]+H36 -> 176 | J37: Yes
A38: PL | B38: Leave Earned | C38: 2025 | G38: 10 | H38: =Table11[[#This Row],[Leave Earned / Cash Payment or Deductable PL2]]+H37 -> 186 | I38: Transfer From Tibbi to Jaipur | J38: Pending to check
A39: PL | B39: Deductable | C39: 2025 | D39: 45985 | E39: 45996 | G39: -12 | H39: =Table11[[#This Row],[Leave Earned / Cash Payment or Deductable PL2]]+H38 -> 174 | I39: in two terms PL taken | J39: Pending to check
A54: Leave Type | B54: Leave Earned / Cash Payment or Deductable PL | C54: Year | D54: From | E54: To | F54: No of Days/ Months | G54: Leave Earned / Cash Payment or Deductable PL2 | H54: Balance on retrun from leave column | I54: Remark | J54: matched with service book
A55: Medical | B55: Leave Earned | D55: 42271 | E55: 42636 | F55: 1 Year | G55: 20 | H55: 20 | J55: Yes
...

Sheet GPF
A1: =COUNTA(A4:A1048576) -> 49 | B1: =COUNTA(B4:B1048576) -> 49 | C1: =COUNTA(C4:C1048576) -> 49 | D1: =COUNTA(D4:D1048576) -> 49 | E1: =COUNTA(E4:E1048576) -> 49 | P1: =MAX(O:O) -> 225562.72 | R1: =COUNTA(R4:R1048576) -> 107
A2: From GA-55 of excel sheet | F2: From SIPF Portal (new) | O2: Calculations | S2: =SUM(S4:S1048576) -> 57 | U2: Last Update on this sheet | V2: 46110
A3: S. No. | B3: Bill No | C3: Bill Date | D3: TV No | E3: TV Date | F3: M | G3: FY | H3: Month | I3: GPF Deduction | J3: DA Arrears | K3: Withdrawl /Claim | L3: Withdrawl Repayment | M3: Other Arrears | N3: Total | O3: New Balance | P3: Interest Rate | Q3: Interest | R3: Remark | S3: Correction Needed | T3: interest by portal
F4: Apr | G4: 2012-2013 | H4: =CONCATENATE(F4,"-",RIGHT(LEFT(G4,4),2)) -> Apr-12 | N4: =I4+J4+L4+M4-K4 -> 0 | O4: =N4 -> 0 | P4: 0.088 | Q4: =O4*P4/12 -> 0 | S4: =IF(OR(R4="",R4="ok"),0,1) -> 0 | AB4: Sum of Total | AP4: Sum of Interest
F5: May | G5: =G4 -> 2012-2013 | H5: =CONCATENATE(F5,"-",RIGHT(LEFT(G5,4),2)) -> May-12 | N5: =I5+J5+L5+M5-K5 -> 0 | O5: =O4+N5 -> 0 | P5: 0.088 | Q5: =O5*P5/12 -> 0 | S5: =IF(OR(R5="",R5="ok"),0,1) -> 0 | AB5: Row Labels | AC5: Jan | AD5: Feb | AE5: Mar | AF5: Apr | AG5: May | AH5: Jun | AI5: Jul | AJ5: Aug | AK5: Sep | AL5: Oct | AM5: Nov | AN5: Dec | AO5: Grand Total | AP5: Row Labels | AQ5: (blank) | AR5: Grand Total | AS5: New Balance
F6: Jun | G6: =G5 -> 2012-2013 | H6: =CONCATENATE(F6,"-",RIGHT(LEFT(G6,4),2)) -> Jun-12 | N6: =I6+J6+L6+M6-K6 -> 0 | O6: =O5+N6 -> 0 | P6: 0.088 | Q6: =O6*P6/12 -> 0 | S6: =IF(OR(R6="",R6="ok"),0,1) -> 0 | AB6: 2012-2013 | AC6: 0 | AD6: 0 | AE6: 0 | AF6: 0 | AG6: 0 | AH6: 0 | AI6: 0 | AJ6: 0 | AK6: 0 | AL6: 0 | AM6: 0 | AN6: 0 | AO6: 0 | AP6: 2012-2013 | AQ6: 0 | AR6: 0 | AS6: =AO6+AR6 -> 0
F7: Jul | G7: =G6 -> 2012-2013 | H7: =CONCATENATE(F7,"-",RIGHT(LEFT(G7,4),2)) -> Jul-12 | N7: =I7+J7+L7+M7-K7 -> 0 | O7: =O6+N7 -> 0 | P7: 0.088 | Q7: =O7*P7/12 -> 0 | S7: =IF(OR(R7="",R7="ok"),0,1) -> 0 | AB7: 2013-2014 | AC7: 0 | AD7: 0 | AE7: 0 | AF7: 0 | AG7: 0 | AH7: 0 | AI7: 0 | AJ7: 0 | AK7: 0 | AL7: 0 | AM7: 0 | AN7: 0 | AO7: 0 | AP7: 2013-2014 | AQ7: 0 | AR7: 0 | AS7: =AO7+AR7 -> 0
F8: Aug | G8: =G7 -> 2012-2013 | H8: =CONCATENATE(F8,"-",RIGHT(LEFT(G8,4),2)) -> Aug-12 | N8: =I8+J8+L8+M8-K8 -> 0 | O8: =O7+N8 -> 0 | P8: 0.088 | Q8: =O8*P8/12 -> 0 | S8: =IF(OR(R8="",R8="ok"),0,1) -> 0 | AB8: 2014-2015 | AC8: 0 | AD8: 0 | AE8: 0 | AF8: 0 | AG8: 0 | AH8: 0 | AI8: 0 | AJ8: 0 | AK8: 0 | AL8: 0 | AM8: 0 | AN8: 0 | AO8: 0 | AP8: 2014-2015 | AQ8: 0 | AR8: 0 | AS8: =AO8+AR8 -> 0
F9: Sep | G9: =G8 -> 2012-2013 | H9: =CONCATENATE(F9,"-",RIGHT(LEFT(G9,4),2)) -> Sep-12 | N9: =I9+J9+L9+M9-K9 -> 0 | O9: =O8+N9 -> 0 | P9: 0.088 | Q9: =O9*P9/12 -> 0 | S9: =IF(OR(R9="",R9="ok"),0,1) -> 0 | AB9: 2015-2016 | AC9: 0 | AD9: 0 | AE9: 0 | AF9: 0 | AG9: 0 | AH9: 0 | AI9: 0 | AJ9: 0 | AK9: 0 | AL9: 0 | AM9: 0 | AN9: 0 | AO9: 0 | AP9: 2015-2016 | AQ9: 0 | AR9: 0 | AS9: =AO9+AR9 -> 0
F10: Oct | G10: =G9 -> 2012-2013 | H10: =CONCATENATE(F10,"-",RIGHT(LEFT(G10,4),2)) -> Oct-12 | N10: =I10+J10+L10+M10-K10 -> 0 | O10: =O9+N10 -> 0 | P10: 0.088 | Q10: =O10*P10/12 -> 0 | S10: =IF(OR(R10="",R10="ok"),0,1) -> 0 | AB10: 2016-2017 | AC10: 0 | AD10: 0 | AE10: 0 | AF10: 0 | AG10: 0 | AH10: 0 | AI10: 0 | AJ10: 0 | AK10: 0 | AL10: 0 | AM10: 0 | AN10: 0 | AO10: 0 | AP10: 2016-2017 | AQ10: 0 | AR10: 0 | AS10: =AO10+AR10 -> 0
F11: Nov | G11: =G10 -> 2012-2013 | H11: =CONCATENATE(F11,"-",RIGHT(LEFT(G11,4),2)) -> Nov-12 | N11: =I11+J11+L11+M11-K11 -> 0 | O11: =O10+N11 -> 0 | P11: 0.088 | Q11: =O11*P11/12 -> 0 | S11: =IF(OR(R11="",R11="ok"),0,1) -> 0 | AB11: 2017-2018 | AC11: 0 | AD11: 0 | AE11: 0 | AF11: 0 | AG11: 0 | AH11: 0 | AI11: 0 | AJ11: 0 | AK11: 0 | AL11: 0 | AM11: 0 | AN11: 0 | AO11: 0 | AP11: 2017-2018 | AQ11: 0 | AR11: 0 | AS11: =AO11+AR11 -> 0
F12: Dec | G12: =G11 -> 2012-2013 | H12: =CONCATENATE(F12,"-",RIGHT(LEFT(G12,4),2)) -> Dec-12 | N12: =I12+J12+L12+M12-K12 -> 0 | O12: =O11+N12 -> 0 | P12: 0.088 | Q12: =O12*P12/12 -> 0 | S12: =IF(OR(R12="",R12="ok"),0,1) -> 0 | AB12: 2018-2019 | AC12: 0 | AD12: 0 | AE12: 0 | AF12: 0 | AG12: 0 | AH12: 0 | AI12: 0 | AJ12: 0 | AK12: 0 | AL12: 0 | AM12: 0 | AN12: 0 | AO12: 0 | AP12: 2018-2019 | AQ12: 0 | AR12: 0 | AS12: =AO12+AR12 -> 0
F13: Jan | G13: =G12 -> 2012-2013 | H13: =CONCATENATE(F13,"-",RIGHT(RIGHT(G13,4),2)) -> Jan-13 | N13: =I13+J13+L13+M13-K13 -> 0 | O13: =O12+N13 -> 0 | P13: 0.088 | Q13: =O13*P13/12 -> 0 | S13: =IF(OR(R13="",R13="ok"),0,1) -> 0 | AB13: 2019-2020 | AC13: 0 | AD13: 0 | AE13: 0 | AF13: 0 | AG13: 0 | AH13: 0 | AI13: 0 | AJ13: 0 | AK13: 0 | AL13: 0 | AM13: 0 | AN13: 0 | AO13: 0 | AP13: 2019-2020 | AQ13: 0 | AR13: 0 | AS13: =AO13+AR13 -> 0
F14: Feb | G14: =G13 -> 2012-2013 | H14: =CONCATENATE(F14,"-",RIGHT(RIGHT(G14,4),2)) -> Feb-13 | N14: =I14+J14+L14+M14-K14 -> 0 | O14: =O13+N14 -> 0 | P14: 0.088 | Q14: =O14*P14/12 -> 0 | S14: =IF(OR(R14="",R14="ok"),0,1) -> 0 | AB14: 2020-2021 | AC14: 0 | AD14: 0 | AE14: 0 | AF14: 0 | AG14: 0 | AH14: 0 | AI14: 0 | AJ14: 0 | AK14: 0 | AL14: 0 | AM14: 5081 | AN14: 0 | AO14: 5081 | AP14: 2020-2021 | AQ14: 150.31292 | AR14: 150.31292 | AS14: =AO14+AR14 -> 5231.3129
F15: Mar | G15: =G14 -> 2012-2013 | H15: =CONCATENATE(F15,"-",RIGHT(RIGHT(G15,4),2)) -> Mar-13 | N15: =I15+J15+L15+M15-K15 -> 0 | O15: =O14+N15 -> 0 | P15: 0.088 | Q15: =O15*P15/12 -> 0 | S15: =IF(OR(R15="",R15="ok"),0,1) -> 0 | AB15: 2021-2022 | AC15: 0 | AD15: 0 | AE15: 0 | AF15: 0 | AG15: 0 | AH15: 0 | AI15: 0 | AJ15: 0 | AK15: 0 | AL15: 0 | AM15: 3387 | AN15: 2616 | AO15: 6003 | AP15: 2021-2022 | AQ15: 533.53397 | AR15: 533.53397 | AS15: =AO15+AR15 -> 6536.534
G16: =G15 -> 2012-2013 | I16: =SUM(I4:I15) -> 0 | J16: =SUM(J4:J15) -> 0 | K16: =SUM(K4:K15) -> 0 | L16: =SUM(L4:L15) -> 0 | M16: =SUM(M4:M15) -> 0 | N16: =SUM(N4:N15) -> 0 | O16: =O15+Q16 -> 0 | Q16: =SUM(Q4:Q15) -> 0 | S16: =IF(OR(R16="",R16="ok"),0,1) -> 0 | AB16: 2022-2023 | AC16: 2114 | AD16: 2100 | AE16: 2100 | AF16: 0 | AG16: 0 | AH16: 7107 | AI16: 2100 | AJ16: 2100 | AK16: 2100 | AL16: 3794 | AM16: 2100 | AN16: 6096 | AO16: 31711 | AP16: 2022-2023 | AQ16: 1970.0971 | AR16: 1970.0971 | AS16: =AO16+AR16 -> 33681.097
F17: Apr | G17: =CONCATENATE(RIGHT(G4,4),"-",RIGHT(G4,4)+1) -> 2013-2014 | H17: =CONCATENATE(F17,"-",RIGHT(LEFT(G17,4),2)) -> Apr-13 | N17: =I17+J17+L17+M17-K17 -> 0 | O17: =O16+N17 -> 0 | P17: 0.087 | Q17: =O17*P17/12 -> 0 | S17: =IF(OR(R17="",R17="ok"),0,1) -> 0 | AB17: 2023-2024 | AC17: 7828 | AD17: 2100 | AE17: 2100 | AF17: 2100 | AG17: 2100 | AH17: 2100 | AI17: 2100 | AJ17: 6276 | AK17: 2100 | AL17: 2100 | AM17: 3794 | AN17: 2100 | AO17: 36798 | AP17: 2023-2024 | AQ17: 4545.4752 | AR17: 4545.4752 | AS17: =AO17+AR17 -> 41343.475
F18: May | G18: =G17 -> 2013-2014 | H18: =CONCATENATE(F18,"-",RIGHT(LEFT(G18,4),2)) -> May-13 | N18: =I18+J18+L18+M18-K18 -> 0 | O18: =O17+N18 -> 0 | P18: 0.087 | Q18: =O18*P18/12 -> 0 | S18: =IF(OR(R18="",R18="ok"),0,1) -> 0 | AB18: 2024-2025 | AC18: 2100 | AD18: 2100 | AE18: 2100 | AF18: 2100 | AG18: 4964 | AH18: 2100 | AI18: 2100 | AJ18: 2100 | AK18: 2100 | AL18: 5894 | AM18: 4428 | AN18: 2100 | AO18: 34186 | AP18: 2024-2025 | AQ18: 7521.3674 | AR18: 7521.3674 | AS18: =AO18+AR18 -> 41707.367
F19: Jun | G19: =G18 -> 2013-2014 | H19: =CONCATENATE(F19,"-",RIGHT(LEFT(G19,4),2)) -> Jun-13 | N19: =I19+J19+L19+M19-K19 -> 0 | O19: =O18+N19 -> 0 | P19: 0.087 | Q19: =O19*P19/12 -> 0 | S19: =IF(OR(R19="",R19="ok"),0,1) -> 0 | AB19: 2025-2026 | AC19: 2100 | AD19: 2100 | AE19: 2100 | AF19: 4314 | AG19: 2100 | AH19: 2100 | AI19: 2100 | AJ19: 2100 | AK19: 2100 | AL19: 3794 | AM19: 5520 | AN19: 2100 | AO19: 32528 | AP19: Grand Total | AQ19: 14720.787 | AR19: 14720.787 | AS19: =AO19+AR19 -> 47248.787
F20: Jul | G20: =G19 -> 2013-2014 | H20: =CONCATENATE(F20,"-",RIGHT(LEFT(G20,4),2)) -> Jul-13 | N20: =I20+J20+L20+M20-K20 -> 0 | O20: =O19+N20 -> 0 | P20: 0.087 | Q20: =O20*P20/12 -> 0 | S20: =IF(OR(R20="",R20="ok"),0,1) -> 0 | AB20: 2026-2027 | AC20: 0 | AD20: 0 | AE20: 0 | AF20: 0 | AG20: 0 | AH20: 0 | AI20: 0 | AJ20: 0 | AK20: 0 | AL20: 0 | AM20: 0 | AN20: 0 | AO20: 0
F21: Aug | G21: =G20 -> 2013-2014 | H21: =CONCATENATE(F21,"-",RIGHT(LEFT(G21,4),2)) -> Aug-13 | N21: =I21+J21+L21+M21-K21 -> 0 | O21: =O20+N21 -> 0 | P21: 0.087 | Q21: =O21*P21/12 -> 0 | S21: =IF(OR(R21="",R21="ok"),0,1) -> 0 | AB21: 2027-2028 | AC21: 0 | AD21: 0 | AE21: 0 | AF21: 0 | AG21: 0 | AH21: 0 | AI21: 0 | AJ21: 0 | AK21: 0 | AL21: 0 | AM21: 0 | AN21: 0 | AO21: 0
F22: Sep | G22: =G21 -> 2013-2014 | H22: =CONCATENATE(F22,"-",RIGHT(LEFT(G22,4),2)) -> Sep-13 | N22: =I22+J22+L22+M22-K22 -> 0 | O22: =O21+N22 -> 0 | P22: 0.087 | Q22: =O22*P22/12 -> 0 | S22: =IF(OR(R22="",R22="ok"),0,1) -> 0 | AB22: 2028-2029 | AC22: 0 | AD22: 0 | AE22: 0 | AF22: 0 | AG22: 0 | AH22: 0 | AI22: 0 | AJ22: 0 | AK22: 0 | AL22: 0 | AM22: 0 | AN22: 0 | AO22: 0
F23: Oct | G23: =G22 -> 2013-2014 | H23: =CONCATENATE(F23,"-",RIGHT(LEFT(G23,4),2)) -> Oct-13 | N23: =I23+J23+L23+M23-K23 -> 0 | O23: =O22+N23 -> 0 | P23: 0.087 | Q23: =O23*P23/12 -> 0 | S23: =IF(OR(R23="",R23="ok"),0,1) -> 0 | AB23: 2029-2030 | AC23: 0 | AD23: 0 | AE23: 0 | AF23: 0 | AG23: 0 | AH23: 0 | AI23: 0 | AJ23: 0 | AK23: 0 | AL23: 0 | AM23: 0 | AN23: 0 | AO23: 0
F24: Nov | G24: =G23 -> 2013-2014 | H24: =CONCATENATE(F24,"-",RIGHT(LEFT(G24,4),2)) -> Nov-13 | N24: =I24+J24+L24+M24-K24 -> 0 | O24: =O23+N24 -> 0 | P24: 0.087 | Q24: =O24*P24/12 -> 0 | S24: =IF(OR(R24="",R24="ok"),0,1) -> 0 | AB24: Grand Total | AC24: 14142 | AD24: 8400 | AE24: 8400 | AF24: 8514 | AG24: 9164 | AH24: 13407 | AI24: 8400 | AJ24: 12576 | AK24: 8400 | AL24: 15582 | AM24: 24310 | AN24: 15012 | AO24: 146307
F25: Dec | G25: =G24 -> 2013-2014 | H25: =CONCATENATE(F25,"-",RIGHT(LEFT(G25,4),2)) -> Dec-13 | N25: =I25+J25+L25+M25-K25 -> 0 | O25: =O24+N25 -> 0 | P25: 0.087 | Q25: =O25*P25/12 -> 0 | S25: =IF(OR(R25="",R25="ok"),0,1) -> 0
F26: Jan | G26: =G25 -> 2013-2014 | H26: =CONCATENATE(F26,"-",RIGHT(RIGHT(G26,4),2)) -> Jan-14 | N26: =I26+J26+L26+M26-K26 -> 0 | O26: =O25+N26 -> 0 | P26: 0.087 | Q26: =O26*P26/12 -> 0 | S26: =IF(OR(R26="",R26="ok"),0,1) -> 0
F27: Feb | G27: =G26 -> 2013-2014 | H27: =CONCATENATE(F27,"-",RIGHT(RIGHT(G27,4),2)) -> Feb-14 | N27: =I27+J27+L27+M27-K27 -> 0 | O27: =O26+N27 -> 0 | P27: 0.087 | Q27: =O27*P27/12 -> 0 | S27: =IF(OR(R27="",R27="ok"),0,1) -> 0
F28: Mar | G28: =G27 -> 2013-2014 | H28: =CONCATENATE(F28,"-",RIGHT(RIGHT(G28,4),2)) -> Mar-14 | N28: =I28+J28+L28+M28-K28 -> 0 | O28: =O27+N28 -> 0 | P28: 0.087 | Q28: =O28*P28/12 -> 0 | S28: =IF(OR(R28="",R28="ok"),0,1) -> 0
G29: =G28 -> 2013-2014 | I29: =SUM(I17:I28) -> 0 | J29: =SUM(J17:J28) -> 0 | K29: =SUM(K17:K28) -> 0 | L29: =SUM(L17:L28) -> 0 | M29: =SUM(M17:M28) -> 0 | N29: =SUM(N17:N28) -> 0 | O29: =O28+Q29 -> 0 | Q29: =SUM(Q17:Q28) -> 0 | S29: =IF(OR(R29="",R29="ok"),0,1) -> 0
F30: Apr | G30: =CONCATENATE(RIGHT(G17,4),"-",RIGHT(G17,4)+1) -> 2014-2015 | H30: =CONCATENATE(F30,"-",RIGHT(LEFT(G30,4),2)) -> Apr-14 | N30: =I30+J30+L30+M30-K30 -> 0 | O30: =O29+N30 -> 0 | P30: 0.087 | Q30: =O30*P30/12 -> 0 | S30: =IF(OR(R30="",R30="ok"),0,1) -> 0
F31: May | G31: =G30 -> 2014-2015 | H31: =CONCATENATE(F31,"-",RIGHT(LEFT(G31,4),2)) -> May-14 | N31: =I31+J31+L31+M31-K31 -> 0 | O31: =O30+N31 -> 0 | P31: 0.087 | Q31: =O31*P31/12 -> 0 | S31: =IF(OR(R31="",R31="ok"),0,1) -> 0
F32: Jun | G32: =G31 -> 2014-2015 | H32: =CONCATENATE(F32,"-",RIGHT(LEFT(G32,4),2)) -> Jun-14 | N32: =I32+J32+L32+M32-K32 -> 0 | O32: =O31+N32 -> 0 | P32: 0.087 | Q32: =O32*P32/12 -> 0 | S32: =IF(OR(R32="",R32="ok"),0,1) -> 0
F33: Jul | G33: =G32 -> 2014-2015 | H33: =CONCATENATE(F33,"-",RIGHT(LEFT(G33,4),2)) -> Jul-14 | N33: =I33+J33+L33+M33-K33 -> 0 | O33: =O32+N33 -> 0 | P33: 0.087 | Q33: =O33*P33/12 -> 0 | S33: =IF(OR(R33="",R33="ok"),0,1) -> 0
F34: Aug | G34: =G33 -> 2014-2015 | H34: =CONCATENATE(F34,"-",RIGHT(LEFT(G34,4),2)) -> Aug-14 | N34: =I34+J34+L34+M34-K34 -> 0 | O34: =O33+N34 -> 0 | P34: 0.087 | Q34: =O34*P34/12 -> 0 | S34: =IF(OR(R34="",R34="ok"),0,1) -> 0
F35: Sep | G35: =G34 -> 2014-2015 | H35: =CONCATENATE(F35,"-",RIGHT(LEFT(G35,4),2)) -> Sep-14 | N35: =I35+J35+L35+M35-K35 -> 0 | O35: =O34+N35 -> 0 | P35: 0.087 | Q35: =O35*P35/12 -> 0 | S35: =IF(OR(R35="",R35="ok"),0,1) -> 0
F36: Oct | G36: =G35 -> 2014-2015 | H36: =CONCATENATE(F36,"-",RIGHT(LEFT(G36,4),2)) -> Oct-14 | N36: =I36+J36+L36+M36-K36 -> 0 | O36: =O35+N36 -> 0 | P36: 0.087 | Q36: =O36*P36/12 -> 0 | S36: =IF(OR(R36="",R36="ok"),0,1) -> 0
F37: Nov | G37: =G36 -> 2014-2015 | H37: =CONCATENATE(F37,"-",RIGHT(LEFT(G37,4),2)) -> Nov-14 | N37: =I37+J37+L37+M37-K37 -> 0 | O37: =O36+N37 -> 0 | P37: 0.087 | Q37: =O37*P37/12 -> 0 | S37: =IF(OR(R37="",R37="ok"),0,1) -> 0
F38: Dec | G38: =G37 -> 2014-2015 | H38: =CONCATENATE(F38,"-",RIGHT(LEFT(G38,4),2)) -> Dec-14 | N38: =I38+J38+L38+M38-K38 -> 0 | O38: =O37+N38 -> 0 | P38: 0.087 | Q38: =O38*P38/12 -> 0 | S38: =IF(OR(R38="",R38="ok"),0,1) -> 0
F39: Jan | G39: =G38 -> 2014-2015 | H39: =CONCATENATE(F39,"-",RIGHT(RIGHT(G39,4),2)) -> Jan-15 | N39: =I39+J39+L39+M39-K39 -> 0 | O39: =O38+N39 -> 0 | P39: 0.087 | Q39: =O39*P39/12 -> 0 | S39: =IF(OR(R39="",R39="ok"),0,1) -> 0
F40: Feb | G40: =G39 -> 2014-2015 | H40: =CONCATENATE(F40,"-",RIGHT(RIGHT(G40,4),2)) -> Feb-15 | N40: =I40+J40+L40+M40-K40 -> 0 | O40: =O39+N40 -> 0 | P40: 0.087 | Q40: =O40*P40/12 -> 0 | S40: =IF(OR(R40="",R40="ok"),0,1) -> 0
...

Sheet SI (SSO ID New)
A1: This Data is From SIPF Portal (Through SSO ID)(NEW) | R1: error at bx4 cell | S1: =BX4 -> 2 | V1: Last Update on this sheet | W1: 46110 | CS1: Differenece of pivot of left most and pivot of (sso id new with detail) this must be zero , if not zero then update both sheets (SI(SSO ID NEW) and SI (SSO ID NEW WITH DETAIL))
R2: error at di5 cell | S2: =DI5 -> 0 | AP2: this pivot table is on left most data | BF2: difference on sso id year wise data and pivot table | CB2: this pivot is on sheet Si(sso id new with detail)
E3: =SUM(Table2[Premium Usual]) -> 472000 | F3: =SUM(Table2[Incremental Premium]) -> 0 | G3: =SUM(Table2[Arrear Usual]) -> 5000 | H3: =SUM(Table2[Loan Installment]) -> 65178 | I3: =SUM(Table2[Loan Interest]) -> 0 | J3: =SUM(Table2[Service Tax]) -> 0 | K3: =SUM(Table2[Recovery Amount]) -> 0 | L3: =SUM(Table2[Total Premium]) -> 542178 | M3: =SUM(Table2[Loan]) -> 434500 | N3: =SUM(Table2[Claim]) -> 0 | O3: =SUM(Table2[Refund]) -> 0 | P3: =SUM(Table2[Check Status with ga 55]) -> 0 | Q3: =SUM(Table2[CORRECTION NEEDED]) -> 1 | X3: this data is from sso id new portal | AP3: Sum of Total (automatic) | BX3: errors
A4: FY | B4: Month | C4: Salary Month | D4: Transaction Mode | E4: Premium Usual | F4: Incremental Premium | G4: Arrear Usual | H4: Loan Installment | I4: Loan Interest | J4: Service Tax | K4: Recovery Amount | L4: Total Premium | M4: Loan | N4: Claim | O4: Refund | P4: Check Status with ga 55 | Q4: CORRECTION NEEDED | R4: TV month or Encashment Month and year | S4: TV month or Encashment Month | T4: TV year or Encashment Year | U4: Total (automatic) | W4: Sr No. | X4: Financial Year | Y4: April | Z4: May | AA4: June | AB4: July | AC4: Aug | AD4: Sept | AE4: Oct | AF4: Nov | AG4: Dec | AH4: Jan | AI4: Feb | AJ4: March | AK4: Total | AL4: Loan | AM4: Claim | AN4: REFUND | AP4: Row Labels | AQ4: Jan | AR4: Feb | AS4: Mar | AT4: Apr | AU4: May | AV4: Jun | AW4: Jul | AX4: Aug | AY4: Sep | AZ4: Oct | BA4: Nov | BB4: Dec | BC4: Grand Total | BF4: Sr No. | BG4: Financial Year | BH4: April | BI4: May | BJ4: June | BK4: July | BL4: Aug | BM4: Sept | BN4: Oct | BO4: Nov | BP4: Dec | BQ4: Jan | BR4: Feb | BS4: March | BT4: Total | BU4: Loan | BV4: Claim | BX4: =SUM(BX5:BX11) -> 2 | CB4: Sum of Total Premium | CS4: Sum | DI4: errors
A5: 2016-2017 | B5: 42614 | C5: 201610 | D5: ONLINE | E5: 2200 | F5: 0 | G5: 0 | H5: 0 | I5: 0 | J5: 0 | K5: 0 | L5: 2200 | M5: 0 | N5: 0 | O5: 0 | P5: OK | Q5: =IF(Table2[[#This Row],[Check Status with ga 55]]="ok",0,1) -> 0 | R5: =IFERROR(CONCATENATE(TEXT(RIGHT(C5,2)*29,"mmm"),"-",RIGHT(LEFT(C5,4),2)),"") -> Oct-16 | S5: =IFERROR((TEXT(RIGHT(C5,2)*29,"mmm")),"") -> Oct | T5: =IFERROR(RIGHT(LEFT(C5,4),2),"") -> 16 | U5: =Table2[[#This Row],[Total Premium]]+Table2[[#This Row],[Loan]] -> 2200 | W5: 1 | X5: 2025-2026 | Y5: 5000 | Z5: 5000 | AA5: 5000 | AB5: 12242 | AC5: 12242 | AD5: 12242 | AE5: 12242 | AF5: 12242 | AG5: 12242 | AH5: 12242 | AI5: 12242 | AJ5: 12242 | AK5: 125178 | AL5: 434500 | AM5: 0 | AN5: 0 | AP5: 2025-2026 | AQ5: 12242 | AR5: 12242 | AS5: 12242 | AT5: 5000 | AU5: 439500 | AV5: 5000 | AW5: 12242 | AX5: 12242 | AY5: 12242 | AZ5: 12242 | BA5: 12242 | BB5: 12242 | BC5: 559678 | BF5: =IFERROR(Table5[[#This Row],[Sr No.]],"") -> 1 | BG5: =IFERROR(Table5[[#This Row],[Financial Year]],"") -> 2025-2026 | BH5: =Y5-AT5 -> 0 | BI5: =Z5-AU5 -> -434500 | BJ5: =AA5-AV5 -> 0 | BK5: =AB5-AW5 -> 0 | BL5: =AC5-AX5 -> 0 | BM5: =AD5-AY5 -> 0 | BN5: =AE5-AZ5 -> 0 | BO5: =AF5-BA5 -> 0 | BP5: =AG5-BB5 -> 0 | BQ5: =AH5-AQ5 -> 0 | BR5: =AI5-AR5 -> 0 | BS5: =AJ5-AS5 -> 0 | BT5: =AK5-BC5 -> -434500 | BX5: =13-COUNTIF(BH5:BT5,0) -> 2 | CB5: Row Labels | CC5: Jan | CD5: Feb | CE5: Mar | CF5: Apr | CG5: May | CH5: Jun | CI5: Jul | CJ5: Aug | CK5: Sep | CL5: Oct | CM5: Nov | CN5: Dec | CO5: Grand Total | CS5: Row Label | CT5: =CC5 -> Jan | CU5: =CD5 -> Feb | CV5: =CE5 -> Mar | CW5: =CF5 -> Apr | CX5: =CG5 -> May | CY5: =CH5 -> Jun | CZ5: =CI5 -> Jul | DA5: =CJ5 -> Aug | ... DF5: =CO5 -> Grand Total | DI5: =SUM(DI6:DI29) -> 0
A6: 2016-2017 | B6: 42430 | C6: 201604 | D6: DED | E6: 1100 | F6: 0 | G6: 0 | H6: 0 | I6: 0 | J6: 0 | K6: 0 | L6: 1100 | M6: 0 | N6: 0 | O6: 0 | P6: OK | Q6: =IF(Table2[[#This Row],[Check Status with ga 55]]="ok",0,"Correction Needed") -> 0 | R6: =IFERROR(CONCATENATE(TEXT(RIGHT(C6,2)*29,"mmm"),"-",RIGHT(LEFT(C6,4),2)),"") -> Apr-16 | S6: =IFERROR((TEXT(RIGHT(C6,2)*29,"mmm")),"") -> Apr | T6: =IFERROR(RIGHT(LEFT(C6,4),2),"") -> 16 | U6: =Table2[[#This Row],[Total Premium]]+Table2[[#This Row],[Loan]] -> 1100 | W6: 2 | X6: 2024-2025 | Y6: 5000 | Z6: 5000 | AA6: 5000 | AB6: 5000 | AC6: 5000 | AD6: 5000 | AE6: 10000 | AF6: 0 | AG6: 5000 | AH6: 5000 | AI6: 5000 | AJ6: 5000 | AK6: 60000 | AL6: 0 | AM6: 0 | AN6: 0 | AP6: 2024-2025 | AQ6: 5000 | AR6: 5000 | AS6: 5000 | AT6: 5000 | AU6: 5000 | AV6: 5000 | AW6: 5000 | AX6: 5000 | AY6: 5000 | AZ6: 10000 | BB6: 5000 | BC6: 60000 | BF6: =IFERROR(Table5[[#This Row],[Sr No.]],"") -> 2 | BG6: =IFERROR(Table5[[#This Row],[Financial Year]],"") -> 2024-2025 | BH6: =Y6-AT6 -> 0 | BI6: =Z6-AU6 -> 0 | BJ6: =AA6-AV6 -> 0 | BK6: =AB6-AW6 -> 0 | BL6: =AC6-AX6 -> 0 | BM6: =AD6-AY6 -> 0 | BN6: =AE6-AZ6 -> 0 | BO6: =AF6-BA6 -> 0 | BP6: =AG6-BB6 -> 0 | BQ6: =AH6-AQ6 -> 0 | BR6: =AI6-AR6 -> 0 | BS6: =AJ6-AS6 -> 0 | BT6: =AK6-BC6 -> 0 | BX6: =13-COUNTIF(BH6:BT6,0) -> 0 | CB6: 2025-2026 | CC6: 12242 | CD6: 12242 | CE6: 12242 | CF6: 5000 | CG6: 439500 | CH6: 5000 | CI6: 12242 | CJ6: 12242 | CK6: 12242 | CL6: 12242 | CM6: 12242 | CN6: 12242 | CO6: 559678 | CS6: =CB6 -> 2025-2026 | CT6: =CC6-AQ5 -> 0 | CU6: =CD6-AR5 -> 0 | CV6: =CE6-AS5 -> 0 | CW6: =CF6-AT5 -> 0 | CX6: =CG6-AU5 -> 0 | CY6: =CH6-AV5 -> 0 | CZ6: =CI6-AW5 -> 0 | DA6: =CJ6-AX5 -> 0 | ... DF6: =CO6-BC5 -> 0 | DI6: =13-COUNTIF(CT6:DF6,0) -> 0
A7: 2016-2017 | B7: 42461 | C7: 201605 | D7: DED | E7: 1100 | F7: 0 | G7: 0 | H7: 0 | I7: 0 | J7: 0 | K7: 0 | L7: 1100 | M7: 0 | N7: 0 | O7: 0 | P7: OK | Q7: =IF(Table2[[#This Row],[Check Status with ga 55]]="ok",0,1) -> 0 | R7: =IFERROR(CONCATENATE(TEXT(RIGHT(C7,2)*29,"mmm"),"-",RIGHT(LEFT(C7,4),2)),"") -> May-16 | S7: =IFERROR((TEXT(RIGHT(C7,2)*29,"mmm")),"") -> May | T7: =IFERROR(RIGHT(LEFT(C7,4),2),"") -> 16 | U7: =Table2[[#This Row],[Total Premium]]+Table2[[#This Row],[Loan]] -> 1100 | W7: 3 | X7: 2023-2024 | Y7: 5000 | Z7: 5000 | AA7: 5000 | AB7: 5000 | AC7: 5000 | AD7: 5000 | AE7: 5000 | AF7: 5000 | AG7: 5000 | AH7: 5000 | AI7: 5000 | AJ7: 5000 | AK7: 60000 | AL7: 0 | AM7: 0 | AN7: 0 | AP7: 2023-2024 | AQ7: 5000 | AR7: 5000 | AS7: 5000 | AT7: 5000 | AU7: 5000 | AV7: 5000 | AW7: 5000 | AX7: 5000 | AY7: 5000 | AZ7: 5000 | BA7: 5000 | BB7: 5000 | BC7: 60000 | BF7: =IFERROR(Table5[[#This Row],[Sr No.]],"") -> 3 | BG7: =IFERROR(Table5[[#This Row],[Financial Year]],"") -> 2023-2024 | BH7: =Y7-AT7 -> 0 | BI7: =Z7-AU7 -> 0 | BJ7: =AA7-AV7 -> 0 | BK7: =AB7-AW7 -> 0 | BL7: =AC7-AX7 -> 0 | BM7: =AD7-AY7 -> 0 | BN7: =AE7-AZ7 -> 0 | BO7: =AF7-BA7 -> 0 | BP7: =AG7-BB7 -> 0 | BQ7: =AH7-AQ7 -> 0 | BR7: =AI7-AR7 -> 0 | BS7: =AJ7-AS7 -> 0 | BT7: =AK7-BC7 -> 0 | BX7: =13-COUNTIF(BH7:BT7,0) -> 0 | CB7: 2024-2025 | CC7: 5000 | CD7: 5000 | CE7: 5000 | CF7: 5000 | CG7: 5000 | CH7: 5000 | CI7: 5000 | CJ7: 5000 | CK7: 5000 | CL7: 10000 | CN7: 5000 | CO7: 60000 | CS7: =CB7 -> 2024-2025 | CT7: =CC7-AQ6 -> 0 | CU7: =CD7-AR6 -> 0 | CV7: =CE7-AS6 -> 0 | CW7: =CF7-AT6 -> 0 | CX7: =CG7-AU6 -> 0 | CY7: =CH7-AV6 -> 0 | CZ7: =CI7-AW6 -> 0 | DA7: =CJ7-AX6 -> 0 | ... DF7: =CO7-BC6 -> 0 | DI7: =13-COUNTIF(CT7:DF7,0) -> 0
A8: 2016-2017 | B8: 42491 | C8: 201606 | D8: DED | E8: 1100 | F8: 0 | G8: 0 | H8: 0 | I8: 0 | J8: 0 | K8: 0 | L8: 1100 | M8: 0 | N8: 0 | O8: 0 | P8: OK | Q8: =IF(Table2[[#This Row],[Check Status with ga 55]]="ok",0,1) -> 0 | R8: =IFERROR(CONCATENATE(TEXT(RIGHT(C8,2)*29,"mmm"),"-",RIGHT(LEFT(C8,4),2)),"") -> Jun-16 | S8: =IFERROR((TEXT(RIGHT(C8,2)*29,"mmm")),"") -> Jun | T8: =IFERROR(RIGHT(LEFT(C8,4),2),"") -> 16 | U8: =Table2[[#This Row],[Total Premium]]+Table2[[#This Row],[Loan]] -> 1100 | W8: 4 | X8: 2022-2023 | Y8: 5000 | Z8: 5000 | AA8: 5000 | AB8: 5000 | AC8: 5000 | AD8: 5000 | AE8: 5000 | AF8: 5000 | AG8: 5000 | AH8: 5000 | AI8: 5000 | AJ8: 5000 | AK8: 60000 | AL8: 0 | AM8: 0 | AN8: 0 | AP8: 2022-2023 | AQ8: 5000 | AR8: 5000 | AS8: 5000 | AT8: 5000 | AU8: 5000 | AV8: 5000 | AW8: 5000 | AX8: 5000 | AY8: 5000 | AZ8: 5000 | BA8: 5000 | BB8: 5000 | BC8: 60000 | BF8: =IFERROR(Table5[[#This Row],[Sr No.]],"") -> 4 | BG8: =IFERROR(Table5[[#This Row],[Financial Year]],"") -> 2022-2023 | BH8: =Y8-AT8 -> 0 | BI8: =Z8-AU8 -> 0 | BJ8: =AA8-AV8 -> 0 | BK8: =AB8-AW8 -> 0 | BL8: =AC8-AX8 -> 0 | BM8: =AD8-AY8 -> 0 | BN8: =AE8-AZ8 -> 0 | BO8: =AF8-BA8 -> 0 | BP8: =AG8-BB8 -> 0 | BQ8: =AH8-AQ8 -> 0 | BR8: =AI8-AR8 -> 0 | BS8: =AJ8-AS8 -> 0 | BT8: =AK8-BC8 -> 0 | BX8: =13-COUNTIF(BH8:BT8,0) -> 0 | CB8: 2023-2024 | CC8: 5000 | CD8: 5000 | CE8: 5000 | CF8: 5000 | CG8: 5000 | CH8: 5000 | CI8: 5000 | CJ8: 5000 | CK8: 5000 | CL8: 5000 | CM8: 5000 | CN8: 5000 | CO8: 60000 | CS8: =CB8 -> 2023-2024 | CT8: =CC8-AQ7 -> 0 | CU8: =CD8-AR7 -> 0 | CV8: =CE8-AS7 -> 0 | CW8: =CF8-AT7 -> 0 | CX8: =CG8-AU7 -> 0 | CY8: =CH8-AV7 -> 0 | CZ8: =CI8-AW7 -> 0 | DA8: =CJ8-AX7 -> 0 | ... DF8: =CO8-BC7 -> 0 | DI8: =13-COUNTIF(CT8:DF8,0) -> 0
A9: 2016-2017 | B9: 42522 | C9: 201607 | D9: DED | E9: 1100 | F9: 0 | G9: 0 | H9: 0 | I9: 0 | J9: 0 | K9: 0 | L9: 1100 | M9: 0 | N9: 0 | O9: 0 | P9: OK | Q9: =IF(Table2[[#This Row],[Check Status with ga 55]]="ok",0,1) -> 0 | R9: =IFERROR(CONCATENATE(TEXT(RIGHT(C9,2)*29,"mmm"),"-",RIGHT(LEFT(C9,4),2)),"") -> Jul-16 | S9: =IFERROR((TEXT(RIGHT(C9,2)*29,"mmm")),"") -> Jul | T9: =IFERROR(RIGHT(LEFT(C9,4),2),"") -> 16 | U9: =Table2[[#This Row],[Total Premium]]+Table2[[#This Row],[Loan]] -> 1100 | W9: 5 | X9: 2021-2022 | Y9: 5000 | Z9: 5000 | AA9: 5000 | AB9: 5000 | AC9: 5000 | AD9: 5000 | AE9: 5000 | AF9: 5000 | AG9: 5000 | AH9: 5000 | AI9: 5000 | AJ9: 5000 | AK9: 60000 | AL9: 0 | AM9: 0 | AN9: 0 | AP9: 2021-2022 | AQ9: 5000 | AR9: 5000 | AS9: 5000 | AT9: 5000 | AU9: 5000 | AV9: 5000 | AW9: 5000 | AX9: 5000 | AY9: 5000 | AZ9: 5000 | BA9: 5000 | BB9: 5000 | BC9: 60000 | BF9: =IFERROR(Table5[[#This Row],[Sr No.]],"") -> 5 | BG9: =IFERROR(Table5[[#This Row],[Financial Year]],"") -> 2021-2022 | BH9: =Y9-AT9 -> 0 | BI9: =Z9-AU9 -> 0 | BJ9: =AA9-AV9 -> 0 | BK9: =AB9-AW9 -> 0 | BL9: =AC9-AX9 -> 0 | BM9: =AD9-AY9 -> 0 | BN9: =AE9-AZ9 -> 0 | BO9: =AF9-BA9 -> 0 | BP9: =AG9-BB9 -> 0 | BQ9: =AH9-AQ9 -> 0 | BR9: =AI9-AR9 -> 0 | BS9: =AJ9-AS9 -> 0 | BT9: =AK9-BC9 -> 0 | BX9: =13-COUNTIF(BH9:BT9,0) -> 0 | CB9: 2022-2023 | CC9: 5000 | CD9: 5000 | CE9: 5000 | CF9: 5000 | CG9: 5000 | CH9: 5000 | CI9: 5000 | CJ9: 5000 | CK9: 5000 | CL9: 5000 | CM9: 5000 | CN9: 5000 | CO9: 60000 | CS9: =CB9 -> 2022-2023 | CT9: =CC9-AQ8 -> 0 | CU9: =CD9-AR8 -> 0 | CV9: =CE9-AS8 -> 0 | CW9: =CF9-AT8 -> 0 | CX9: =CG9-AU8 -> 0 | CY9: =CH9-AV8 -> 0 | CZ9: =CI9-AW8 -> 0 | DA9: =CJ9-AX8 -> 0 | ... DF9: =CO9-BC8 -> 0 | DI9: =13-COUNTIF(CT9:DF9,0) -> 0
A10: 2016-2017 | B10: 42552 | C10: 201608 | D10: DED | E10: 1100 | F10: 0 | G10: 0 | H10: 0 | I10: 0 | J10: 0 | K10: 0 | L10: 1100 | M10: 0 | N10: 0 | O10: 0 | P10: OK | Q10: =IF(Table2[[#This Row],[Check Status with ga 55]]="ok",0,1) -> 0 | R10: =IFERROR(CONCATENATE(TEXT(RIGHT(C10,2)*29,"mmm"),"-",RIGHT(LEFT(C10,4),2)),"") -> Aug-16 | S10: =IFERROR((TEXT(RIGHT(C10,2)*29,"mmm")),"") -> Aug | T10: =IFERROR(RIGHT(LEFT(C10,4),2),"") -> 16 | U10: =Table2[[#This Row],[Total Premium]]+Table2[[#This Row],[Loan]] -> 1100 | W10: 6 | X10: 2020-2021 | Y10: 0 | Z10: 5000 | AA10: 10000 | AB10: 5000 | AC10: 5000 | AD10: 5000 | AE10: 5000 | AF10: 5000 | AG10: 5000 | AH10: 5000 | AI10: 5000 | AJ10: 5000 | AK10: 60000 | AL10: 0 | AM10: 0 | AN10: 0 | AP10: 2020-2021 | AQ10: 5000 | AR10: 5000 | AS10: 5000 | AT10: 0 | AU10: 5000 | AV10: 10000 | AW10: 5000 | AX10: 5000 | AY10: 5000 | AZ10: 5000 | BA10: 5000 | BB10: 5000 | BC10: 60000 | BF10: =IFERROR(Table5[[#This Row],[Sr No.]],"") -> 6 | BG10: =IFERROR(Table5[[#This Row],[Financial Year]],"") -> 2020-2021 | BH10: =Y10-AT10 -> 0 | BI10: =Z10-AU10 -> 0 | BJ10: =AA10-AV10 -> 0 | BK10: =AB10-AW10 -> 0 | BL10: =AC10-AX10 -> 0 | BM10: =AD10-AY10 -> 0 | BN10: =AE10-AZ10 -> 0 | BO10: =AF10-BA10 -> 0 | BP10: =AG10-BB10 -> 0 | BQ10: =AH10-AQ10 -> 0 | BR10: =AI10-AR10 -> 0 | BS10: =AJ10-AS10 -> 0 | BT10: =AK10-BC10 -> 0 | BX10: =13-COUNTIF(BH10:BT10,0) -> 0 | CB10: 2021-2022 | CC10: 5000 | CD10: 5000 | CE10: 5000 | CF10: 5000 | CG10: 5000 | CH10: 5000 | CI10: 5000 | CJ10: 5000 | CK10: 5000 | CL10: 5000 | CM10: 5000 | CN10: 5000 | CO10: 60000 | CS10: =CB10 -> 2021-2022 | CT10: =CC10-AQ9 -> 0 | CU10: =CD10-AR9 -> 0 | CV10: =CE10-AS9 -> 0 | CW10: =CF10-AT9 -> 0 | CX10: =CG10-AU9 -> 0 | CY10: =CH10-AV9 -> 0 | CZ10: =CI10-AW9 -> 0 | DA10: =CJ10-AX9 -> 0 | ... DF10: =CO10-BC9 -> 0 | DI10: =13-COUNTIF(CT10:DF10,0) -> 0
A11: 2016-2017 | B11: 42583 | C11: 201609 | D11: DED | E11: 1100 | F11: 0 | G11: 0 | H11: 0 | I11: 0 | J11: 0 | K11: 0 | L11: 1100 | M11: 0 | N11: 0 | O11: 0 | P11: OK | Q11: =IF(Table2[[#This Row],[Check Status with ga 55]]="ok",0,1) -> 0 | R11: =IFERROR(CONCATENATE(TEXT(RIGHT(C11,2)*29,"mmm"),"-",RIGHT(LEFT(C11,4),2)),"") -> Sep-16 | S11: =IFERROR((TEXT(RIGHT(C11,2)*29,"mmm")),"") -> Sep | T11: =IFERROR(RIGHT(LEFT(C11,4),2),"") -> 16 | U11: =Table2[[#This Row],[Total Premium]]+Table2[[#This Row],[Loan]] -> 1100 | W11: 7 | X11: 2019-2020 | Y11: 3000 | Z11: 3000 | AA11: 3000 | AB11: 3000 | AC11: 3000 | AD11: 3000 | AE11: 3000 | AF11: 3000 | AG11: 3000 | AH11: 3000 | AI11: 3000 | AJ11: 3000 | AK11: 36000 | AL11: 0 | AM11: 0 | AN11: 0 | AP11: 2019-2020 | AQ11: 3000 | AR11: 3000 | AS11: 3000 | AT11: 3000 | AU11: 3000 | AV11: 3000 | AW11: 3000 | AX11: 3000 | AY11: 3000 | AZ11: 3000 | BA11: 3000 | BB11: 3000 | BC11: 36000 | BF11: =IFERROR(Table5[[#This Row],[Sr No.]],"") -> 7 | BG11: =IFERROR(Table5[[#This Row],[Financial Year]],"") -> 2019-2020 | BH11: =Y11-AT11 -> 0 | BI11: =Z11-AU11 -> 0 | BJ11: =AA11-AV11 -> 0 | BK11: =AB11-AW11 -> 0 | BL11: =AC11-AX11 -> 0 | BM11: =AD11-AY11 -> 0 | BN11: =AE11-AZ11 -> 0 | BO11: =AF11-BA11 -> 0 | BP11: =AG11-BB11 -> 0 | BQ11: =AH11-AQ11 -> 0 | BR11: =AI11-AR11 -> 0 | BS11: =AJ11-AS11 -> 0 | BT11: =AK11-BC11 -> 0 | BX11: =13-COUNTIF(BH11:BT11,0) -> 0 | CB11: 2020-2021 | CC11: 5000 | CD11: 5000 | CE11: 5000 | CG11: 5000 | CH11: 10000 | CI11: 5000 | CJ11: 5000 | CK11: 5000 | CL11: 5000 | CM11: 5000 | CN11: 5000 | CO11: 60000 | CS11: =CB11 -> 2020-2021 | CT11: =CC11-AQ10 -> 0 | CU11: =CD11-AR10 -> 0 | CV11: =CE11-AS10 -> 0 | CW11: =CF11-AT10 -> 0 | CX11: =CG11-AU10 -> 0 | CY11: =CH11-AV10 -> 0 | CZ11: =CI11-AW10 -> 0 | DA11: =CJ11-AX10 -> 0 | ... DF11: =CO11-BC10 -> 0 | DI11: =13-COUNTIF(CT11:DF11,0) -> 0
A12: 2016-2017 | B12: 42644 | D12: ONLINE | E12: 0 | F12: 0 | G12: 0 | H12: 0 | I12: 0 | J12: 0 | K12: 0 | L12: 0 | M12: 0 | N12: 0 | O12: 0 | P12: OK | Q12: =IF(Table2[[#This Row],[Check Status with ga 55]]="ok",0,1) -> 0 | R12: =IFERROR(CONCATENATE(TEXT(RIGHT(C12,2)*29,"mmm"),"-",RIGHT(LEFT(C12,4),2)),"") | S12: =IFERROR((TEXT(RIGHT(C12,2)*29,"mmm")),"") | T12: =IFERROR(RIGHT(LEFT(C12,4),2),"") | U12: =Table2[[#This Row],[Total Premium]]+Table2[[#This Row],[Loan]] -> 0 | W12: 8 | X12: 2018-2019 | Y12: 3000 | Z12: 3000 | AA12: 3000 | AB12: 3000 | AC12: 3000 | AD12: 3000 | AE12: 3000 | AF12: 3000 | AG12: 0 | AH12: 3000 | AI12: 6000 | AJ12: 3000 | AK12: 36000 | AL12: 0 | AM12: 0 | AN12: 0 | AP12: 2018-2019 | AQ12: 3000 | AR12: 6000 | AS12: 3000 | AT12: 3000 | AU12: 3000 | AV12: 3000 | AW12: 3000 | AX12: 3000 | AY12: 3000 | AZ12: 3000 | BA12: 3000 | BC12: 36000 | BF12: =IFERROR(Table5[[#This Row],[Sr No.]],"") -> 8 | BG12: =IFERROR(Table5[[#This Row],[Financial Year]],"") -> 2018-2019 | BH12: =Y12-AT12 -> 0 | BI12: =Z12-AU12 -> 0 | BJ12: =AA12-AV12 -> 0 | BK12: =AB12-AW12 -> 0 | BL12: =AC12-AX12 -> 0 | BM12: =AD12-AY12 -> 0 | BN12: =AE12-AZ12 -> 0 | BO12: =AF12-BA12 -> 0 | BP12: =AG12-BB12 -> 0 | BQ12: =AH12-AQ12 -> 0 | BR12: =AI12-AR12 -> 0 | BS12: =AJ12-AS12 -> 0 | BT12: =AK12-BC12 -> 0 | BX12: =13-COUNTIF(BH12:BT12,0) -> 0 | CB12: 2019-2020 | CC12: 3000 | CD12: 3000 | CE12: 3000 | CF12: 3000 | CG12: 3000 | CH12: 3000 | CI12: 3000 | CJ12: 3000 | CK12: 3000 | CL12: 3000 | CM12: 3000 | CN12: 3000 | CO12: 36000 | CS12: =CB12 -> 2019-2020 | CT12: =CC12-AQ11 -> 0 | CU12: =CD12-AR11 -> 0 | CV12: =CE12-AS11 -> 0 | CW12: =CF12-AT11 -> 0 | CX12: =CG12-AU11 -> 0 | CY12: =CH12-AV11 -> 0 | CZ12: =CI12-AW11 -> 0 | DA12: =CJ12-AX11 -> 0 | ... DF12: =CO12-BC11 -> 0 | DI12: =13-COUNTIF(CT12:DF12,0) -> 0
A13: 2016-2017 | B13: 42675 | C13: 201612 | D13: DED | E13: 1100 | F13: 0 | G13: 0 | H13: 0 | I13: 0 | J13: 0 | K13: 0 | L13: 1100 | M13: 0 | N13: 0 | O13: 0 | P13: OK | Q13: =IF(Table2[[#This Row],[Check Status with ga 55]]="ok",0,1) -> 0 | R13: =IFERROR(CONCATENATE(TEXT(RIGHT(C13,2)*29,"mmm"),"-",RIGHT(LEFT(C13,4),2)),"") -> Dec-16 | S13: =IFERROR((TEXT(RIGHT(C13,2)*29,"mmm")),"") -> Dec | T13: =IFERROR(RIGHT(LEFT(C13,4),2),"") -> 16 | U13: =Table2[[#This Row],[Total Premium]]+Table2[[#This Row],[Loan]] -> 1100 | W13: 9 | X13: 2017-2018 | Y13: 2650 | Z13: 2650 | AA13: 2650 | AB13: 2650 | AC13: 2650 | AD13: 2650 | AE13: 2650 | AF13: 2650 | AG13: 2650 | AH13: 2650 | AI13: 2650 | AJ13: 2650 | AK13: 31800 | AL13: 0 | AM13: 0 | AN13: 0 | AP13: 2017-2018 | AQ13: 2650 | AR13: 2650 | AS13: 2650 | AT13: 2650 | AU13: 2650 | AV13: 2650 | AW13: 2650 | AX13: 2650 | AY13: 2650 | AZ13: 2650 | BA13: 2650 | BB13: 2650 | BC13: 31800 | BF13: =IFERROR(Table5[[#This Row],[Sr No.]],"") -> 9 | BG13: =IFERROR(Table5[[#This Row],[Financial Year]],"") -> 2017-2018 | BH13: =Y13-AT13 -> 0 | BI13: =Z13-AU13 -> 0 | BJ13: =AA13-AV13 -> 0 | BK13: =AB13-AW13 -> 0 | BL13: =AC13-AX13 -> 0 | BM13: =AD13-AY13 -> 0 | BN13: =AE13-AZ13 -> 0 | BO13: =AF13-BA13 -> 0 | BP13: =AG13-BB13 -> 0 | BQ13: =AH13-AQ13 -> 0 | BR13: =AI13-AR13 -> 0 | BS13: =AJ13-AS13 -> 0 | BT13: =AK13-BC13 -> 0 | BX13: =13-COUNTIF(BH13:BT13,0) -> 0 | CB13: 2018-2019 | CC13: 3000 | CD13: 6000 | CE13: 3000 | CF13: 3000 | CG13: 3000 | CH13: 3000 | CI13: 3000 | CJ13: 3000 | CK13: 3000 | CL13: 3000 | CM13: 3000 | CO13: 36000 | CS13: =CB13 -> 2018-2019 | CT13: =CC13-AQ12 -> 0 | CU13: =CD13-AR12 -> 0 | CV13: =CE13-AS12 -> 0 | CW13: =CF13-AT12 -> 0 | CX13: =CG13-AU12 -> 0 | CY13: =CH13-AV12 -> 0 | CZ13: =CI13-AW12 -> 0 | DA13: =CJ13-AX12 -> 0 | ... DF13: =CO13-BC12 -> 0 | DI13: =13-COUNTIF(CT13:DF13,0) -> 0
